# Исправление парсинга downloadUrl в ответе сервера

## Проблема

При интеграции с новой API сверки файлов возникла проблема с обработкой ответа сервера. Сервер работал корректно, создавал файлы и загружал их в облако, но код в Odoo не мог найти downloadUrl для скачивания файлов.

### Симптомы
- Сервер успешно создавал файлы и загружал их в Яндекс Облако
- В логах Odoo появлялось сообщение: "Отсутствуют downloadUrls, проверяем наличие локальных файлов"
- Fallback механизм не работал, так как локальные файлы недоступны через HTTP
- Ошибка: "Сервер создал файлы, но они недоступны для скачивания"

### Анализ логов сервера
Сервер возвращал корректный ответ с downloadUrl:
```json
{
  "success": true,
  "message": "Файлы успешно созданы",
  "summary": {
    "reports": {
      "main": {
        "downloadUrl": "https://airtable-clone.storage.yandexcloud.net/uploads/..."
      },
      "test": {
        "downloadUrl": "https://airtable-clone.storage.yandexcloud.net/uploads/..."
      }
    }
  }
}
```

## Причина проблемы

Код в `reconciliation.py` искал downloadUrl в неправильном месте структуры ответа:

**Старый код:**
```python
download_urls = resp_data.get('downloadUrls', {})
main_file_url = download_urls.get('main')
test_file_url = download_urls.get('test')
```

**Проблема:** Сервер не возвращает `downloadUrls` в корне ответа.

## Решение

Обновлен код для правильного извлечения downloadUrl из структуры ответа:

**Новый код:**
```python
# Извлекаем downloadUrl из новой структуры ответа
summary = resp_data.get('summary', {})
reports = summary.get('reports', {})

main_file_url = reports.get('main', {}).get('downloadUrl')
test_file_url = reports.get('test', {}).get('downloadUrl')
```

### Дополнительные улучшения

1. **Улучшен fallback механизм:**
   ```python
   # Используем правильный API endpoint для скачивания
   main_file_url = f"{API_SERVER_BASE_URL}/api/download/{base_filename}_main.xlsx"
   test_file_url = f"{API_SERVER_BASE_URL}/api/download/{base_filename}_test.xlsx"
   ```

2. **Добавлена проверка на пустые данные:**
   ```python
   if not data:
       _logger.warning(f"Нет данных для контрагента {contragent.name}. Использовать диапазон: {use_range}")
       raise UserError(_("Нет данных для экспорта по контрагенту %s") % contragent.name)
   ```

3. **Улучшено логирование:**
   ```python
   _logger.info(f"Количество записей для экспорта: {len(data)}")
   ```

## Результат

После исправления:
- ✅ Сервер успешно создает файлы и загружает их в облако
- ✅ Odoo правильно извлекает downloadUrl из ответа сервера
- ✅ Файлы доступны для скачивания через облачные URL
- ✅ Fallback механизм работает корректно при необходимости
- ✅ Понятные сообщения об ошибках при отсутствии данных

## Файлы изменены

- `addons/amanat/models/reconciliation.py` - исправлен парсинг ответа сервера

## Дата исправления

16 июля 2025 г. 